Workbook
Name Category: Cleaned_Data!$Q$2:$Q$3807
Name Cost_Per_Unit: Cleaned_Data!$U$2:$U$3807
Name Low_Stock: 'Insights Summary'!$I$2:$I$3807
Name Next_Restock_Due: Cleaned_Data!$J$2:$J$3807
Name Overdues: 'Insights Summary'!$AC$2:$AC$3807
Name Product_ID: Cleaned_Data!$A$2:$A$3807
Name Product_Name: Cleaned_Data!$P$2:$P$3807
Name Product_Status: Cleaned_Data!$K$2:$K$3807
Name Quantity_in_Stock: Cleaned_Data!$S$2:$S$3807
Name Recorder_Level: Cleaned_Data!$T$2:$T$3807
Name Recorder_Tag: Cleaned_Data!$X$2:$X$3807
Name Restock_Flag: Cleaned_Data!$Y$2:$Y$3807
Name Slicer_2_Category: #N/A
Name Slicer_Recorder_Tag: #N/A
Name Slicer_Stock_Status1: #N/A
Name Slicer_Supplier_Name: #N/A
Name Stock_Status: Cleaned_Data!$W$2:$W$3807
Name Store_Location: Cleaned_Data!$L$2:$L$3807
Name Supplier_Name: Cleaned_Data!$R$2:$R$3807
Name Total_Value: Cleaned_Data!$V$2:$V$3807
Name VLookup_Data: Cleaned_Data!$P$1:$Y$3807

Sheet Inventory Dataset
A1: Product ID | B1: Product Name | C1: Category | D1: Supplier Name | E1: Quantity in Stock | F1: Reorder Level | G1: Cost per unit(₹) | H1: Total Value (₹) | I1: Last Restocked Date | J1: Next Restock Due | K1: Product Status | L1: Store Location
A2: P8270 | B2: Management Plus | C2: Clothing | D2: Global Traders | E2: 179 | F2: 34 | G2: 14653.28 | H2: 2622937.1 | I2: 45848 | J2: 45883 | K2: Actv | L2: Pune Store
A3: P6734 | B3: Glass Mini | C3: Toys | D3: Global Traders | E3: 121 | F3: 94 | G3: 9212.02 | H3: 1114654.4 | I3: 45770 | J3: 45886 | L3: Mumbai Store
A4: P9322 | B4: Government Max | C4: Toys | D4: Omni Suppliers | F4: 72 | G4: 19399.7 | I4: 45777 | J4: 45906 | K4: active | L4: Pune Store
A5: P7949 | B5: Kitchen Plus | C5: Furniture | D5: Omni Suppliers | E5: 129 | F5: 83 | G5: 19844.62 | H5: 2559956 | I5: 45830 | J5: 45898 | K5: ACTIVE | L5: Online
A6: P2184 | B6: Image X | C6: Clothing | D6: Omni Suppliers | E6: 57 | F6: 41 | G6: 190.97 | H6: 10885.29 | I6: 45848 | J6: 45896 | K6: active | L6: Ahmedabad Branch
A7: P9666 | B7: Computer Plus | C7: Toys | D7: Omni Suppliers | E7: 58 | F7: 61 | G7: 980.98 | H7: 56896.84 | I7: 45808 | J7: 45926 | K7: active | L7: Online
A8: P3747 | B8: Democrat Lite | C8: Toys | E8: 14 | F8: 81 | G8: 1857.6 | H8: 26006.4 | I8: 45739 | J8: 45875 | K8: Actv | L8: Mumbai Store
A9: P4005 | B9: hundred lite | C9: Electronics | D9: QuickStock | E9: 50 | F9: 74 | G9: 19665.46 | H9: 983273 | I9: 45808 | J9: 45868 | K9: ACTIVE | L9: Online
A10: P2528 | B10: Plan Plus | C10: Groceries | D10: RetailMart Inc | E10: 130 | F10: 70 | G10: 13622.14 | H10: 1770878.2 | I10: 45671 | J10: 45888 | K10: discontinued | L10: Mumbai Store
A11: P6393 | B11: Change Pro | C11: Groceries | D11: Omni Suppliers | E11: 131 | F11: 79 | G11: 11287.6 | H11: 1478675.6 | I11: 45688 | J11: 45853 | K11: active | L11: Pune Store
A12: P8513 | B12: Deep Max | C12: Groceries | D12: RetailMart Inc | E12: 52 | F12: 21 | G12: 13700.45 | H12: 712423.4 | I12: 45804 | J12: 45918 | K12: active | L12: Ahmedabad Branch
A13: P6486 | B13: Find X | C13: Groceries | D13: ABC Pvt Ltd | E13: 187 | F13: 90 | G13: 12219.43 | H13: 2285033.4 | I13: 45756 | J13: 45940 | K13: discon | L13: Ahmedabad Branch
A14: P1775 | B14: Nothing Lite | C14: Furniture | D14: QuickStock | E14: 174 | F14: 54 | G14: 18190.94 | H14: 3165223.6 | I14: 45750 | J14: 45868 | K14: Inactive | L14: Delhi Warehouse
A15: P2585 | B15: Wait Max | C15: Groceries | D15: Omni Suppliers | E15: 103 | F15: 23 | G15: 6268.64 | H15: 645669.92 | I15: 45707 | J15: 45899 | K15: discon | L15: Delhi Warehouse
A16: P4843 | B16: Old Mini | C16: Groceries | D16: Omni Suppliers | E16: 53 | F16: 82 | G16: 16853.58 | H16: 893239.74 | I16: 45724 | J16: 45914 | K16: discontinued | L16: Pune Store
A17: P6675 | B17: Before Lite | C17: Clothing | D17: QuickStock | E17: 161 | F17: 93 | G17: 17901.81 | H17: 2882191.4 | I17: 45780 | J17: 45873 | L17: Ahmedabad Branch
A18: P8629 | B18: Support Plus | C18: Clothing | D18: Omni Suppliers | E18: 189 | F18: 59 | G18: 16898.45 | H18: 3193807 | I18: 45827 | J18: 45864 | K18: discontinued | L18: Ahmedabad Branch
A19: P8916 | B19: else pro | C19: Furniture | D19: Global Traders | E19: 81 | F19: 72 | G19: 11755.69 | H19: 952210.89 | I19: 45747 | J19: 45890 | K19: discon | L19: Ahmedabad Branch
A20: P5859 | B20: When Lite | C20: Electronics | D20: QuickStock | E20: 187 | F20: 60 | G20: 5960.66 | H20: 1114643.4 | I20: 45779 | J20: 45940 | K20: active | L20: Pune Store
A21: P1064 | B21: Blood Max | C21: Toys | D21: QuickStock | E21: 88 | F21: 90 | G21: 8496.86 | H21: 747723.68 | I21: 45816 | J21: 45865 | K21: discon | L21: Mumbai Store
A22: P3027 | B22: Quite Mini | C22: Groceries | D22: Omni Suppliers | E22: 135 | F22: 82 | G22: 16318.46 | H22: 2202992.1 | I22: 45675 | J22: 45940 | K22: ACTIVE | L22: Delhi Warehouse
A23: P7736 | B23: Eat Plus | C23: Clothing | D23: Omni Suppliers | E23: 135 | G23: 15814 | H23: 2134890 | I23: 45745 | J23: 45891 | K23: ACTIVE | L23: Ahmedabad Branch
A24: P6892 | B24: Least Mini | C24: Clothing | D24: Omni Suppliers | E24: 40 | F24: 47 | G24: 17268.91 | H24: 690756.4 | I24: 45793 | J24: 45936 | K24: active | L24: Mumbai Store
A25: P4104 | B25: Those Lite | C25: Groceries | D25: Omni Suppliers | E25: 47 | F25: 42 | G25: 13393.38 | H25: 629488.86 | I25: 45685 | J25: 45876 | K25: active | L25: Ahmedabad Branch
A26: P9996 | B26: Training Plus | C26: Clothing | D26: RetailMart Inc | E26: 98 | F26: 63 | G26: 12769.27 | H26: 1251388.5 | I26: 45841 | J26: 45864 | K26: Inactive | L26: Mumbai Store
A27: P9154 | B27: Table Pro | C27: Furniture | D27: QuickStock | E27: 34 | F27: 84 | G27: 7689.39 | H27: 261439.26 | I27: 45774 | J27: 45925 | L27: Online
A28: P9110 | B28: american plus | C28: Electronics | D28: QuickStock | E28: 130 | F28: 20 | G28: 14448.5 | H28: 1878305 | I28: 45838 | J28: 45862 | K28: ACTIVE | L28: Online
A29: P1502 | B29: History Plus | C29: Toys | D29: Omni Suppliers | E29: 141 | F29: 46 | G29: 10478.52 | H29: 1477471.3 | I29: 45707 | J29: 45938 | K29: Inactive | L29: Pune Store
A30: P6134 | B30: Color Lite | C30: Groceries | D30: Global Traders | E30: 89 | F30: 61 | G30: 8814.76 | H30: 784513.64 | I30: 45804 | J30: 45893 | K30: Inactive | L30: Delhi Warehouse
A31: P8858 | B31: Remain Pro | C31: Furniture | E31: 62 | F31: 71 | G31: 11287.35 | H31: 699815.7 | I31: 45763 | J31: 45854 | K31: ACTIVE | L31: Pune Store
A32: P7019 | B32: Seem X | C32: Electronics | D32: ABC Pvt Ltd | E32: 150 | F32: 34 | G32: 15123.25 | H32: 2268487.5 | I32: 45785 | J32: 45908 | L32: Mumbai Store
A33: P2059 | B33: West Max | C33: Toys | D33: QuickStock | E33: 12 | F33: 51 | G33: 11997.37 | H33: 143968.44 | I33: 45811 | J33: 45894 | K33: ACTIVE | L33: Delhi Warehouse
A34: P4157 | B34: Inside Lite | C34: Electronics | D34: ABC Pvt Ltd | E34: 27 | F34: 85 | G34: 12505.86 | H34: 337658.22 | I34: 45708 | J34: 45905 | K34: ACTIVE | L34: Mumbai Store
A35: P3693 | B35: Question Plus | C35: Clothing | D35: Global Traders | E35: 27 | F35: 47 | G35: 4407.89 | H35: 119013.03 | I35: 45768 | J35: 45865 | K35: Inactive | L35: Delhi Warehouse
A36: P6450 | B36: Better X | C36: Toys | D36: Global Traders | E36: 127 | F36: 81 | G36: 2245.54 | H36: 285183.58 | I36: 45834 | J36: 45929 | L36: Ahmedabad Branch
A37: P2306 | B37: Church Mini | C37: Groceries | E37: 189 | F37: 96 | G37: 17221.58 | H37: 3254878.6 | I37: 45845 | J37: 45882 | K37: discontinued | L37: Online
A38: P8526 | B38: Kitchen X | C38: Groceries | D38: RetailMart Inc | E38: 197 | F38: 91 | G38: 10705.08 | H38: 2108900.8 | I38: 45822 | J38: 45915 | K38: discontinued | L38: Delhi Warehouse
A39: P5413 | B39: Anyone X | C39: Furniture | D39: QuickStock | E39: 164 | F39: 70 | G39: 5424.78 | H39: 889663.92 | I39: 45800 | J39: 45916 | K39: Inactive | L39: Delhi Warehouse
A40: P1663 | B40: Peace Lite | C40: Furniture | D40: QuickStock | E40: 58 | F40: 51 | G40: 10399.87 | H40: 603192.46 | I40: 45787 | J40: 45895 | K40: Inactive | L40: Online
...

Sheet Cleaned_Data
A1: Product ID | B1: Product Name | C1: Category | D1: Supplier Name | E1: Quantity in Stock | F1: Reorder Level | G1: Cost per unit(₹) | H1: Total Value (₹) | I1: Last Restocked Date | J1: Next Restock Due | K1: Product Status | L1: Store Location | M1: 1 Product Name | N1: 1 Category | O1: 1 Supplier Name | P1: 2 Product Name | Q1: 2 Category | R1: 2 Supplier Name | S1: Quantity in Stock | T1: Reorder Level | U1: Cost per unit(₹) | V1: Total Value (₹) | W1: Stock Status | X1: Recorder Tag | Y1: Restock Flag
A2: P8270 | B2: Management Plus | C2: Clothing | D2: Global Traders | E2: 179 | F2: 34 | G2: 14653.28 | H2: 2622937.1 | I2: 45848 | J2: 45883 | K2: Actv | L2: Pune Store | M2: =PROPER(TRIM(SUBSTITUTE(B2,"###"," "))) -> Management Plus | N2: =PROPER(TRIM(SUBSTITUTE(C2,"###"," "))) -> Clothing | O2: =PROPER(TRIM(SUBSTITUTE(D2,"###"," "))) -> Global Traders | P2: =IF(M2="","Unknown",M2) -> Management Plus | Q2: =IF(N2="","Unknown",N2) -> Clothing | R2: =IF(O2="","Others",O2) -> Global Traders | S2: =VALUE(E2) -> 179 | T2: =VALUE(F2) -> 34 | U2: =VALUE(G2) -> 14653.28 | V2: =S2*U2 -> 2622937.1 | W2: {=IF((Quantity_in_Stock)=0,"Out of Stock", IF((Quantity_in_Stock)<=(Recorder_Level),"Low Stock","In Stock"))} -> In Stock | X2: {=IF(Quantity_in_Stock<Recorder_Level, "Yes", "No")} -> No | Y2: {=IF((Quantity_in_Stock)<=(Recorder_Level),1,0)} -> 0
A3: P6734 | B3: Glass Mini | C3: Toys | D3: Global Traders | E3: 121 | F3: 94 | G3: 9212.02 | H3: 1114654.4 | I3: 45770 | J3: 45886 | L3: Mumbai Store | M3: =PROPER(TRIM(SUBSTITUTE(B3,"###"," "))) -> Glass Mini | N3: =PROPER(TRIM(SUBSTITUTE(C3,"###"," "))) -> Toys | O3: =PROPER(TRIM(SUBSTITUTE(D3,"###"," "))) -> Global Traders | P3: =IF(M3="","Unknown",M3) -> Glass Mini | Q3: =IF(N3="","Unknown",N3) -> Toys | R3: =IF(O3="","Others",O3) -> Global Traders | S3: =VALUE(E3) -> 121 | T3: =VALUE(F3) -> 94 | U3: =VALUE(G3) -> 9212.02 | V3: =E3*G3 -> 1114654.4 | W3: In Stock | X3: No | Y3: 0
A4: P9322 | B4: Government Max | C4: Toys | D4: Omni Suppliers | F4: 72 | G4: 19399.7 | I4: 45777 | J4: 45906 | K4: active | L4: Pune Store | M4: =PROPER(TRIM(SUBSTITUTE(B4,"###"," "))) -> Government Max | N4: =PROPER(TRIM(SUBSTITUTE(C4,"###"," "))) -> Toys | O4: =PROPER(TRIM(SUBSTITUTE(D4,"###"," "))) -> Omni Suppliers | P4: =IF(M4="","Unknown",M4) -> Government Max | Q4: =IF(N4="","Unknown",N4) -> Toys | R4: =IF(O4="","Others",O4) -> Omni Suppliers | S4: =VALUE(E4) -> 0 | T4: =VALUE(F4) -> 72 | U4: =VALUE(G4) -> 19399.7 | V4: =E4*G4 -> 0 | W4: Out of Stock | X4: Yes | Y4: 1
A5: P7949 | B5: Kitchen Plus | C5: Furniture | D5: Omni Suppliers | E5: 129 | F5: 83 | G5: 19844.62 | H5: 2559956 | I5: 45830 | J5: 45898 | K5: ACTIVE | L5: Online | M5: =PROPER(TRIM(SUBSTITUTE(B5,"###"," "))) -> Kitchen Plus | N5: =PROPER(TRIM(SUBSTITUTE(C5,"###"," "))) -> Furniture | O5: =PROPER(TRIM(SUBSTITUTE(D5,"###"," "))) -> Omni Suppliers | P5: =IF(M5="","Unknown",M5) -> Kitchen Plus | Q5: =IF(N5="","Unknown",N5) -> Furniture | R5: =IF(O5="","Others",O5) -> Omni Suppliers | S5: =VALUE(E5) -> 129 | T5: =VALUE(F5) -> 83 | U5: =VALUE(G5) -> 19844.62 | V5: =E5*G5 -> 2559956 | W5: In Stock | X5: No | Y5: 0
A6: P2184 | B6: Image X | C6: Clothing | D6: Omni Suppliers | E6: 57 | F6: 41 | G6: 190.97 | H6: 10885.29 | I6: 45848 | J6: 45896 | K6: active | L6: Ahmedabad Branch | M6: =PROPER(TRIM(SUBSTITUTE(B6,"###"," "))) -> Image X | N6: =PROPER(TRIM(SUBSTITUTE(C6,"###"," "))) -> Clothing | O6: =PROPER(TRIM(SUBSTITUTE(D6,"###"," "))) -> Omni Suppliers | P6: =IF(M6="","Unknown",M6) -> Image X | Q6: =IF(N6="","Unknown",N6) -> Clothing | R6: =IF(O6="","Others",O6) -> Omni Suppliers | S6: =VALUE(E6) -> 57 | T6: =VALUE(F6) -> 41 | U6: =VALUE(G6) -> 190.97 | V6: =E6*G6 -> 10885.29 | W6: In Stock | X6: No | Y6: 0
A7: P9666 | B7: Computer Plus | C7: Toys | D7: Omni Suppliers | E7: 58 | F7: 61 | G7: 980.98 | H7: 56896.84 | I7: 45808 | J7: 45926 | K7: active | L7: Online | M7: =PROPER(TRIM(SUBSTITUTE(B7,"###"," "))) -> Computer Plus | N7: =PROPER(TRIM(SUBSTITUTE(C7,"###"," "))) -> Toys | O7: =PROPER(TRIM(SUBSTITUTE(D7,"###"," "))) -> Omni Suppliers | P7: =IF(M7="","Unknown",M7) -> Computer Plus | Q7: =IF(N7="","Unknown",N7) -> Toys | R7: =IF(O7="","Others",O7) -> Omni Suppliers | S7: =VALUE(E7) -> 58 | T7: =VALUE(F7) -> 61 | U7: =VALUE(G7) -> 980.98 | V7: =E7*G7 -> 56896.84 | W7: Low Stock | X7: Yes | Y7: 1
A8: P3747 | B8: Democrat Lite | C8: Toys | E8: 14 | F8: 81 | G8: 1857.6 | H8: 26006.4 | I8: 45739 | J8: 45875 | K8: Actv | L8: Mumbai Store | M8: =PROPER(TRIM(SUBSTITUTE(B8,"###"," "))) -> Democrat Lite | N8: =PROPER(TRIM(SUBSTITUTE(C8,"###"," "))) -> Toys | O8: =PROPER(TRIM(SUBSTITUTE(D8,"###"," "))) | P8: =IF(M8="","Unknown",M8) -> Democrat Lite | Q8: =IF(N8="","Unknown",N8) -> Toys | R8: =IF(O8="","Others",O8) -> Others | S8: =VALUE(E8) -> 14 | T8: =VALUE(F8) -> 81 | U8: =VALUE(G8) -> 1857.6 | V8: =E8*G8 -> 26006.4 | W8: Low Stock | X8: Yes | Y8: 1
A9: P4005 | B9: hundred lite | C9: Electronics | D9: QuickStock | E9: 50 | F9: 74 | G9: 19665.46 | H9: 983273 | I9: 45808 | J9: 45868 | K9: ACTIVE | L9: Online | M9: =PROPER(TRIM(SUBSTITUTE(B9,"###"," "))) -> Hundred Lite | N9: =PROPER(TRIM(SUBSTITUTE(C9,"###"," "))) -> Electronics | O9: =PROPER(TRIM(SUBSTITUTE(D9,"###"," "))) -> Quickstock | P9: =IF(M9="","Unknown",M9) -> Hundred Lite | Q9: =IF(N9="","Unknown",N9) -> Electronics | R9: =IF(O9="","Others",O9) -> Quickstock | S9: =VALUE(E9) -> 50 | T9: =VALUE(F9) -> 74 | U9: =VALUE(G9) -> 19665.46 | V9: =E9*G9 -> 983273 | W9: Low Stock | X9: Yes | Y9: 1
A10: P2528 | B10: Plan Plus | C10: Groceries | D10: RetailMart Inc | E10: 130 | F10: 70 | G10: 13622.14 | H10: 1770878.2 | I10: 45671 | J10: 45888 | K10: discontinued | L10: Mumbai Store | M10: =PROPER(TRIM(SUBSTITUTE(B10,"###"," "))) -> Plan Plus | N10: =PROPER(TRIM(SUBSTITUTE(C10,"###"," "))) -> Groceries | O10: =PROPER(TRIM(SUBSTITUTE(D10,"###"," "))) -> Retailmart Inc | P10: =IF(M10="","Unknown",M10) -> Plan Plus | Q10: =IF(N10="","Unknown",N10) -> Groceries | R10: =IF(O10="","Others",O10) -> Retailmart Inc | S10: =VALUE(E10) -> 130 | T10: =VALUE(F10) -> 70 | U10: =VALUE(G10) -> 13622.14 | V10: =E10*G10 -> 1770878.2 | W10: In Stock | X10: No | Y10: 0
A11: P6393 | B11: Change Pro | C11: Groceries | D11: Omni Suppliers | E11: 131 | F11: 79 | G11: 11287.6 | H11: 1478675.6 | I11: 45688 | J11: 45853 | K11: active | L11: Pune Store | M11: =PROPER(TRIM(SUBSTITUTE(B11,"###"," "))) -> Change Pro | N11: =PROPER(TRIM(SUBSTITUTE(C11,"###"," "))) -> Groceries | O11: =PROPER(TRIM(SUBSTITUTE(D11,"###"," "))) -> Omni Suppliers | P11: =IF(M11="","Unknown",M11) -> Change Pro | Q11: =IF(N11="","Unknown",N11) -> Groceries | R11: =IF(O11="","Others",O11) -> Omni Suppliers | S11: =VALUE(E11) -> 131 | T11: =VALUE(F11) -> 79 | U11: =VALUE(G11) -> 11287.6 | V11: =E11*G11 -> 1478675.6 | W11: In Stock | X11: No | Y11: 0
A12: P8513 | B12: Deep Max | C12: Groceries | D12: RetailMart Inc | E12: 52 | F12: 21 | G12: 13700.45 | H12: 712423.4 | I12: 45804 | J12: 45918 | K12: active | L12: Ahmedabad Branch | M12: =PROPER(TRIM(SUBSTITUTE(B12,"###"," "))) -> Deep Max | N12: =PROPER(TRIM(SUBSTITUTE(C12,"###"," "))) -> Groceries | O12: =PROPER(TRIM(SUBSTITUTE(D12,"###"," "))) -> Retailmart Inc | P12: =IF(M12="","Unknown",M12) -> Deep Max | Q12: =IF(N12="","Unknown",N12) -> Groceries | R12: =IF(O12="","Others",O12) -> Retailmart Inc | S12: =VALUE(E12) -> 52 | T12: =VALUE(F12) -> 21 | U12: =VALUE(G12) -> 13700.45 | V12: =E12*G12 -> 712423.4 | W12: In Stock | X12: No | Y12: 0
A13: P6486 | B13: Find X | C13: Groceries | D13: ABC Pvt Ltd | E13: 187 | F13: 90 | G13: 12219.43 | H13: 2285033.4 | I13: 45756 | J13: 45940 | K13: discon | L13: Ahmedabad Branch | M13: =PROPER(TRIM(SUBSTITUTE(B13,"###"," "))) -> Find X | N13: =PROPER(TRIM(SUBSTITUTE(C13,"###"," "))) -> Groceries | O13: =PROPER(TRIM(SUBSTITUTE(D13,"###"," "))) -> Abc Pvt Ltd | P13: =IF(M13="","Unknown",M13) -> Find X | Q13: =IF(N13="","Unknown",N13) -> Groceries | R13: =IF(O13="","Others",O13) -> Abc Pvt Ltd | S13: =VALUE(E13) -> 187 | T13: =VALUE(F13) -> 90 | U13: =VALUE(G13) -> 12219.43 | V13: =E13*G13 -> 2285033.4 | W13: In Stock | X13: No | Y13: 0
A14: P1775 | B14: Nothing Lite | C14: Furniture | D14: QuickStock | E14: 174 | F14: 54 | G14: 18190.94 | H14: 3165223.6 | I14: 45750 | J14: 45868 | K14: Inactive | L14: Delhi Warehouse | M14: =PROPER(TRIM(SUBSTITUTE(B14,"###"," "))) -> Nothing Lite | N14: =PROPER(TRIM(SUBSTITUTE(C14,"###"," "))) -> Furniture | O14: =PROPER(TRIM(SUBSTITUTE(D14,"###"," "))) -> Quickstock | P14: =IF(M14="","Unknown",M14) -> Nothing Lite | Q14: =IF(N14="","Unknown",N14) -> Furniture | R14: =IF(O14="","Others",O14) -> Quickstock | S14: =VALUE(E14) -> 174 | T14: =VALUE(F14) -> 54 | U14: =VALUE(G14) -> 18190.94 | V14: =E14*G14 -> 3165223.6 | W14: In Stock | X14: No | Y14: 0
A15: P2585 | B15: Wait Max | C15: Groceries | D15: Omni Suppliers | E15: 103 | F15: 23 | G15: 6268.64 | H15: 645669.92 | I15: 45707 | J15: 45899 | K15: discon | L15: Delhi Warehouse | M15: =PROPER(TRIM(SUBSTITUTE(B15,"###"," "))) -> Wait Max | N15: =PROPER(TRIM(SUBSTITUTE(C15,"###"," "))) -> Groceries | O15: =PROPER(TRIM(SUBSTITUTE(D15,"###"," "))) -> Omni Suppliers | P15: =IF(M15="","Unknown",M15) -> Wait Max | Q15: =IF(N15="","Unknown",N15) -> Groceries | R15: =IF(O15="","Others",O15) -> Omni Suppliers | S15: =VALUE(E15) -> 103 | T15: =VALUE(F15) -> 23 | U15: =VALUE(G15) -> 6268.64 | V15: =E15*G15 -> 645669.92 | W15: In Stock | X15: No | Y15: 0
A16: P4843 | B16: Old Mini | C16: Groceries | D16: Omni Suppliers | E16: 53 | F16: 82 | G16: 16853.58 | H16: 893239.74 | I16: 45724 | J16: 45914 | K16: discontinued | L16: Pune Store | M16: =PROPER(TRIM(SUBSTITUTE(B16,"###"," "))) -> Old Mini | N16: =PROPER(TRIM(SUBSTITUTE(C16,"###"," "))) -> Groceries | O16: =PROPER(TRIM(SUBSTITUTE(D16,"###"," "))) -> Omni Suppliers | P16: =IF(M16="","Unknown",M16) -> Old Mini | Q16: =IF(N16="","Unknown",N16) -> Groceries | R16: =IF(O16="","Others",O16) -> Omni Suppliers | S16: =VALUE(E16) -> 53 | T16: =VALUE(F16) -> 82 | U16: =VALUE(G16) -> 16853.58 | V16: =E16*G16 -> 893239.74 | W16: Low Stock | X16: Yes | Y16: 1
A17: P6675 | B17: Before Lite | C17: Clothing | D17: QuickStock | E17: 161 | F17: 93 | G17: 17901.81 | H17: 2882191.4 | I17: 45780 | J17: 45873 | L17: Ahmedabad Branch | M17: =PROPER(TRIM(SUBSTITUTE(B17,"###"," "))) -> Before Lite | N17: =PROPER(TRIM(SUBSTITUTE(C17,"###"," "))) -> Clothing | O17: =PROPER(TRIM(SUBSTITUTE(D17,"###"," "))) -> Quickstock | P17: =IF(M17="","Unknown",M17) -> Before Lite | Q17: =IF(N17="","Unknown",N17) -> Clothing | R17: =IF(O17="","Others",O17) -> Quickstock | S17: =VALUE(E17) -> 161 | T17: =VALUE(F17) -> 93 | U17: =VALUE(G17) -> 17901.81 | V17: =E17*G17 -> 2882191.4 | W17: In Stock | X17: No | Y17: 0
A18: P8629 | B18: Support Plus | C18: Clothing | D18: Omni Suppliers | E18: 189 | F18: 59 | G18: 16898.45 | H18: 3193807 | I18: 45827 | J18: 45864 | K18: discontinued | L18: Ahmedabad Branch | M18: =PROPER(TRIM(SUBSTITUTE(B18,"###"," "))) -> Support Plus | N18: =PROPER(TRIM(SUBSTITUTE(C18,"###"," "))) -> Clothing | O18: =PROPER(TRIM(SUBSTITUTE(D18,"###"," "))) -> Omni Suppliers | P18: =IF(M18="","Unknown",M18) -> Support Plus | Q18: =IF(N18="","Unknown",N18) -> Clothing | R18: =IF(O18="","Others",O18) -> Omni Suppliers | S18: =VALUE(E18) -> 189 | T18: =VALUE(F18) -> 59 | U18: =VALUE(G18) -> 16898.45 | V18: =E18*G18 -> 3193807.1 | W18: In Stock | X18: No | Y18: 0
A19: P8916 | B19: else pro | C19: Furniture | D19: Global Traders | E19: 81 | F19: 72 | G19: 11755.69 | H19: 952210.89 | I19: 45747 | J19: 45890 | K19: discon | L19: Ahmedabad Branch | M19: =PROPER(TRIM(SUBSTITUTE(B19,"###"," "))) -> Else Pro | N19: =PROPER(TRIM(SUBSTITUTE(C19,"###"," "))) -> Furniture | O19: =PROPER(TRIM(SUBSTITUTE(D19,"###"," "))) -> Global Traders | P19: =IF(M19="","Unknown",M19) -> Else Pro | Q19: =IF(N19="","Unknown",N19) -> Furniture | R19: =IF(O19="","Others",O19) -> Global Traders | S19: =VALUE(E19) -> 81 | T19: =VALUE(F19) -> 72 | U19: =VALUE(G19) -> 11755.69 | V19: =E19*G19 -> 952210.89 | W19: In Stock | X19: No | Y19: 0
A20: P5859 | B20: When Lite | C20: Electronics | D20: QuickStock | E20: 187 | F20: 60 | G20: 5960.66 | H20: 1114643.4 | I20: 45779 | J20: 45940 | K20: active | L20: Pune Store | M20: =PROPER(TRIM(SUBSTITUTE(B20,"###"," "))) -> When Lite | N20: =PROPER(TRIM(SUBSTITUTE(C20,"###"," "))) -> Electronics | O20: =PROPER(TRIM(SUBSTITUTE(D20,"###"," "))) -> Quickstock | P20: =IF(M20="","Unknown",M20) -> When Lite | Q20: =IF(N20="","Unknown",N20) -> Electronics | R20: =IF(O20="","Others",O20) -> Quickstock | S20: =VALUE(E20) -> 187 | T20: =VALUE(F20) -> 60 | U20: =VALUE(G20) -> 5960.66 | V20: =E20*G20 -> 1114643.4 | W20: In Stock | X20: No | Y20: 0
A21: P1064 | B21: Blood Max | C21: Toys | D21: QuickStock | E21: 88 | F21: 90 | G21: 8496.86 | H21: 747723.68 | I21: 45816 | J21: 45865 | K21: discon | L21: Mumbai Store | M21: =PROPER(TRIM(SUBSTITUTE(B21,"###"," "))) -> Blood Max | N21: =PROPER(TRIM(SUBSTITUTE(C21,"###"," "))) -> Toys | O21: =PROPER(TRIM(SUBSTITUTE(D21,"###"," "))) -> Quickstock | P21: =IF(M21="","Unknown",M21) -> Blood Max | Q21: =IF(N21="","Unknown",N21) -> Toys | R21: =IF(O21="","Others",O21) -> Quickstock | S21: =VALUE(E21) -> 88 | T21: =VALUE(F21) -> 90 | U21: =VALUE(G21) -> 8496.86 | V21: =E21*G21 -> 747723.68 | W21: Low Stock | X21: Yes | Y21: 1
A22: P3027 | B22: Quite Mini | C22: Groceries | D22: Omni Suppliers | E22: 135 | F22: 82 | G22: 16318.46 | H22: 2202992.1 | I22: 45675 | J22: 45940 | K22: ACTIVE | L22: Delhi Warehouse | M22: =PROPER(TRIM(SUBSTITUTE(B22,"###"," "))) -> Quite Mini | N22: =PROPER(TRIM(SUBSTITUTE(C22,"###"," "))) -> Groceries | O22: =PROPER(TRIM(SUBSTITUTE(D22,"###"," "))) -> Omni Suppliers | P22: =IF(M22="","Unknown",M22) -> Quite Mini | Q22: =IF(N22="","Unknown",N22) -> Groceries | R22: =IF(O22="","Others",O22) -> Omni Suppliers | S22: =VALUE(E22) -> 135 | T22: =VALUE(F22) -> 82 | U22: =VALUE(G22) -> 16318.46 | V22: =E22*G22 -> 2202992.1 | W22: In Stock | X22: No | Y22: 0
A23: P7736 | B23: Eat Plus | C23: Clothing | D23: Omni Suppliers | E23: 135 | G23: 15814 | H23: 2134890 | I23: 45745 | J23: 45891 | K23: ACTIVE | L23: Ahmedabad Branch | M23: =PROPER(TRIM(SUBSTITUTE(B23,"###"," "))) -> Eat Plus | N23: =PROPER(TRIM(SUBSTITUTE(C23,"###"," "))) -> Clothing | O23: =PROPER(TRIM(SUBSTITUTE(D23,"###"," "))) -> Omni Suppliers | P23: =IF(M23="","Unknown",M23) -> Eat Plus | Q23: =IF(N23="","Unknown",N23) -> Clothing | R23: =IF(O23="","Others",O23) -> Omni Suppliers | S23: =VALUE(E23) -> 135 | T23: =VALUE(F23) -> 0 | U23: =VALUE(G23) -> 15814 | V23: =E23*G23 -> 2134890 | W23: In Stock | X23: No | Y23: 0
A24: P6892 | B24: Least Mini | C24: Clothing | D24: Omni Suppliers | E24: 40 | F24: 47 | G24: 17268.91 | H24: 690756.4 | I24: 45793 | J24: 45936 | K24: active | L24: Mumbai Store | M24: =PROPER(TRIM(SUBSTITUTE(B24,"###"," "))) -> Least Mini | N24: =PROPER(TRIM(SUBSTITUTE(C24,"###"," "))) -> Clothing | O24: =PROPER(TRIM(SUBSTITUTE(D24,"###"," "))) -> Omni Suppliers | P24: =IF(M24="","Unknown",M24) -> Least Mini | Q24: =IF(N24="","Unknown",N24) -> Clothing | R24: =IF(O24="","Others",O24) -> Omni Suppliers | S24: =VALUE(E24) -> 40 | T24: =VALUE(F24) -> 47 | U24: =VALUE(G24) -> 17268.91 | V24: =E24*G24 -> 690756.4 | W24: Low Stock | X24: Yes | Y24: 1
A25: P4104 | B25: Those Lite | C25: Groceries | D25: Omni Suppliers | E25: 47 | F25: 42 | G25: 13393.38 | H25: 629488.86 | I25: 45685 | J25: 45876 | K25: active | L25: Ahmedabad Branch | M25: =PROPER(TRIM(SUBSTITUTE(B25,"###"," "))) -> Those Lite | N25: =PROPER(TRIM(SUBSTITUTE(C25,"###"," "))) -> Groceries | O25: =PROPER(TRIM(SUBSTITUTE(D25,"###"," "))) -> Omni Suppliers | P25: =IF(M25="","Unknown",M25) -> Those Lite | Q25: =IF(N25="","Unknown",N25) -> Groceries | R25: =IF(O25="","Others",O25) -> Omni Suppliers | S25: =VALUE(E25) -> 47 | T25: =VALUE(F25) -> 42 | U25: =VALUE(G25) -> 13393.38 | V25: =E25*G25 -> 629488.86 | W25: In Stock | X25: No | Y25: 0
A26: P9996 | B26: Training Plus | C26: Clothing | D26: RetailMart Inc | E26: 98 | F26: 63 | G26: 12769.27 | H26: 1251388.5 | I26: 45841 | J26: 45864 | K26: Inactive | L26: Mumbai Store | M26: =PROPER(TRIM(SUBSTITUTE(B26,"###"," "))) -> Training Plus | N26: =PROPER(TRIM(SUBSTITUTE(C26,"###"," "))) -> Clothing | O26: =PROPER(TRIM(SUBSTITUTE(D26,"###"," "))) -> Retailmart Inc | P26: =IF(M26="","Unknown",M26) -> Training Plus | Q26: =IF(N26="","Unknown",N26) -> Clothing | R26: =IF(O26="","Others",O26) -> Retailmart Inc | S26: =VALUE(E26) -> 98 | T26: =VALUE(F26) -> 63 | U26: =VALUE(G26) -> 12769.27 | V26: =E26*G26 -> 1251388.5 | W26: In Stock | X26: No | Y26: 0
A27: P9154 | B27: Table Pro | C27: Furniture | D27: QuickStock | E27: 34 | F27: 84 | G27: 7689.39 | H27: 261439.26 | I27: 45774 | J27: 45925 | L27: Online | M27: =PROPER(TRIM(SUBSTITUTE(B27,"###"," "))) -> Table Pro | N27: =PROPER(TRIM(SUBSTITUTE(C27,"###"," "))) -> Furniture | O27: =PROPER(TRIM(SUBSTITUTE(D27,"###"," "))) -> Quickstock | P27: =IF(M27="","Unknown",M27) -> Table Pro | Q27: =IF(N27="","Unknown",N27) -> Furniture | R27: =IF(O27="","Others",O27) -> Quickstock | S27: =VALUE(E27) -> 34 | T27: =VALUE(F27) -> 84 | U27: =VALUE(G27) -> 7689.39 | V27: =E27*G27 -> 261439.26 | W27: Low Stock | X27: Yes | Y27: 1
A28: P9110 | B28: american plus | C28: Electronics | D28: QuickStock | E28: 130 | F28: 20 | G28: 14448.5 | H28: 1878305 | I28: 45838 | J28: 45862 | K28: ACTIVE | L28: Online | M28: =PROPER(TRIM(SUBSTITUTE(B28,"###"," "))) -> American Plus | N28: =PROPER(TRIM(SUBSTITUTE(C28,"###"," "))) -> Electronics | O28: =PROPER(TRIM(SUBSTITUTE(D28,"###"," "))) -> Quickstock | P28: =IF(M28="","Unknown",M28) -> American Plus | Q28: =IF(N28="","Unknown",N28) -> Electronics | R28: =IF(O28="","Others",O28) -> Quickstock | S28: =VALUE(E28) -> 130 | T28: =VALUE(F28) -> 20 | U28: =VALUE(G28) -> 14448.5 | V28: =E28*G28 -> 1878305 | W28: In Stock | X28: No | Y28: 0
A29: P1502 | B29: History Plus | C29: Toys | D29: Omni Suppliers | E29: 141 | F29: 46 | G29: 10478.52 | H29: 1477471.3 | I29: 45707 | J29: 45938 | K29: Inactive | L29: Pune Store | M29: =PROPER(TRIM(SUBSTITUTE(B29,"###"," "))) -> History Plus | N29: =PROPER(TRIM(SUBSTITUTE(C29,"###"," "))) -> Toys | O29: =PROPER(TRIM(SUBSTITUTE(D29,"###"," "))) -> Omni Suppliers | P29: =IF(M29="","Unknown",M29) -> History Plus | Q29: =IF(N29="","Unknown",N29) -> Toys | R29: =IF(O29="","Others",O29) -> Omni Suppliers | S29: =VALUE(E29) -> 141 | T29: =VALUE(F29) -> 46 | U29: =VALUE(G29) -> 10478.52 | V29: =E29*G29 -> 1477471.3 | W29: In Stock | X29: No | Y29: 0
A30: P6134 | B30: Color Lite | C30: Groceries | D30: Global Traders | E30: 89 | F30: 61 | G30: 8814.76 | H30: 784513.64 | I30: 45804 | J30: 45893 | K30: Inactive | L30: Delhi Warehouse | M30: =PROPER(TRIM(SUBSTITUTE(B30,"###"," "))) -> Color Lite | N30: =PROPER(TRIM(SUBSTITUTE(C30,"###"," "))) -> Groceries | O30: =PROPER(TRIM(SUBSTITUTE(D30,"###"," "))) -> Global Traders | P30: =IF(M30="","Unknown",M30) -> Color Lite | Q30: =IF(N30="","Unknown",N30) -> Groceries | R30: =IF(O30="","Others",O30) -> Global Traders | S30: =VALUE(E30) -> 89 | T30: =VALUE(F30) -> 61 | U30: =VALUE(G30) -> 8814.76 | V30: =E30*G30 -> 784513.64 | W30: In Stock | X30: No | Y30: 0
A31: P8858 | B31: Remain Pro | C31: Furniture | E31: 62 | F31: 71 | G31: 11287.35 | H31: 699815.7 | I31: 45763 | J31: 45854 | K31: ACTIVE | L31: Pune Store | M31: =PROPER(TRIM(SUBSTITUTE(B31,"###"," "))) -> Remain Pro | N31: =PROPER(TRIM(SUBSTITUTE(C31,"###"," "))) -> Furniture | O31: =PROPER(TRIM(SUBSTITUTE(D31,"###"," "))) | P31: =IF(M31="","Unknown",M31) -> Remain Pro | Q31: =IF(N31="","Unknown",N31) -> Furniture | R31: =IF(O31="","Others",O31) -> Others | S31: =VALUE(E31) -> 62 | T31: =VALUE(F31) -> 71 | U31: =VALUE(G31) -> 11287.35 | V31: =E31*G31 -> 699815.7 | W31: Low Stock | X31: Yes | Y31: 1
A32: P7019 | B32: Seem X | C32: Electronics | D32: ABC Pvt Ltd | E32: 150 | F32: 34 | G32: 15123.25 | H32: 2268487.5 | I32: 45785 | J32: 45908 | L32: Mumbai Store | M32: =PROPER(TRIM(SUBSTITUTE(B32,"###"," "))) -> Seem X | N32: =PROPER(TRIM(SUBSTITUTE(C32,"###"," "))) -> Electronics | O32: =PROPER(TRIM(SUBSTITUTE(D32,"###"," "))) -> Abc Pvt Ltd | P32: =IF(M32="","Unknown",M32) -> Seem X | Q32: =IF(N32="","Unknown",N32) -> Electronics | R32: =IF(O32="","Others",O32) -> Abc Pvt Ltd | S32: =VALUE(E32) -> 150 | T32: =VALUE(F32) -> 34 | U32: =VALUE(G32) -> 15123.25 | V32: =E32*G32 -> 2268487.5 | W32: In Stock | X32: No | Y32: 0
A33: P2059 | B33: West Max | C33: Toys | D33: QuickStock | E33: 12 | F33: 51 | G33: 11997.37 | H33: 143968.44 | I33: 45811 | J33: 45894 | K33: ACTIVE | L33: Delhi Warehouse | M33: =PROPER(TRIM(SUBSTITUTE(B33,"###"," "))) -> West Max | N33: =PROPER(TRIM(SUBSTITUTE(C33,"###"," "))) -> Toys | O33: =PROPER(TRIM(SUBSTITUTE(D33,"###"," "))) -> Quickstock | P33: =IF(M33="","Unknown",M33) -> West Max | Q33: =IF(N33="","Unknown",N33) -> Toys | R33: =IF(O33="","Others",O33) -> Quickstock | S33: =VALUE(E33) -> 12 | T33: =VALUE(F33) -> 51 | U33: =VALUE(G33) -> 11997.37 | V33: =E33*G33 -> 143968.44 | W33: Low Stock | X33: Yes | Y33: 1
A34: P4157 | B34: Inside Lite | C34: Electronics | D34: ABC Pvt Ltd | E34: 27 | F34: 85 | G34: 12505.86 | H34: 337658.22 | I34: 45708 | J34: 45905 | K34: ACTIVE | L34: Mumbai Store | M34: =PROPER(TRIM(SUBSTITUTE(B34,"###"," "))) -> Inside Lite | N34: =PROPER(TRIM(SUBSTITUTE(C34,"###"," "))) -> Electronics | O34: =PROPER(TRIM(SUBSTITUTE(D34,"###"," "))) -> Abc Pvt Ltd | P34: =IF(M34="","Unknown",M34) -> Inside Lite | Q34: =IF(N34="","Unknown",N34) -> Electronics | R34: =IF(O34="","Others",O34) -> Abc Pvt Ltd | S34: =VALUE(E34) -> 27 | T34: =VALUE(F34) -> 85 | U34: =VALUE(G34) -> 12505.86 | V34: =E34*G34 -> 337658.22 | W34: Low Stock | X34: Yes | Y34: 1
A35: P3693 | B35: Question Plus | C35: Clothing | D35: Global Traders | E35: 27 | F35: 47 | G35: 4407.89 | H35: 119013.03 | I35: 45768 | J35: 45865 | K35: Inactive | L35: Delhi Warehouse | M35: =PROPER(TRIM(SUBSTITUTE(B35,"###"," "))) -> Question Plus | N35: =PROPER(TRIM(SUBSTITUTE(C35,"###"," "))) -> Clothing | O35: =PROPER(TRIM(SUBSTITUTE(D35,"###"," "))) -> Global Traders | P35: =IF(M35="","Unknown",M35) -> Question Plus | Q35: =IF(N35="","Unknown",N35) -> Clothing | R35: =IF(O35="","Others",O35) -> Global Traders | S35: =VALUE(E35) -> 27 | T35: =VALUE(F35) -> 47 | U35: =VALUE(G35) -> 4407.89 | V35: =E35*G35 -> 119013.03 | W35: Low Stock | X35: Yes | Y35: 1
A36: P6450 | B36: Better X | C36: Toys | D36: Global Traders | E36: 127 | F36: 81 | G36: 2245.54 | H36: 285183.58 | I36: 45834 | J36: 45929 | L36: Ahmedabad Branch | M36: =PROPER(TRIM(SUBSTITUTE(B36,"###"," "))) -> Better X | N36: =PROPER(TRIM(SUBSTITUTE(C36,"###"," "))) -> Toys | O36: =PROPER(TRIM(SUBSTITUTE(D36,"###"," "))) -> Global Traders | P36: =IF(M36="","Unknown",M36) -> Better X | Q36: =IF(N36="","Unknown",N36) -> Toys | R36: =IF(O36="","Others",O36) -> Global Traders | S36: =VALUE(E36) -> 127 | T36: =VALUE(F36) -> 81 | U36: =VALUE(G36) -> 2245.54 | V36: =E36*G36 -> 285183.58 | W36: In Stock | X36: No | Y36: 0
A37: P2306 | B37: Church Mini | C37: Groceries | E37: 189 | F37: 96 | G37: 17221.58 | H37: 3254878.6 | I37: 45845 | J37: 45882 | K37: discontinued | L37: Online | M37: =PROPER(TRIM(SUBSTITUTE(B37,"###"," "))) -> Church Mini | N37: =PROPER(TRIM(SUBSTITUTE(C37,"###"," "))) -> Groceries | O37: =PROPER(TRIM(SUBSTITUTE(D37,"###"," "))) | P37: =IF(M37="","Unknown",M37) -> Church Mini | Q37: =IF(N37="","Unknown",N37) -> Groceries | R37: =IF(O37="","Others",O37) -> Others | S37: =VALUE(E37) -> 189 | T37: =VALUE(F37) -> 96 | U37: =VALUE(G37) -> 17221.58 | V37: =E37*G37 -> 3254878.6 | W37: In Stock | X37: No | Y37: 0
A38: P8526 | B38: Kitchen X | C38: Groceries | D38: RetailMart Inc | E38: 197 | F38: 91 | G38: 10705.08 | H38: 2108900.8 | I38: 45822 | J38: 45915 | K38: discontinued | L38: Delhi Warehouse | M38: =PROPER(TRIM(SUBSTITUTE(B38,"###"," "))) -> Kitchen X | N38: =PROPER(TRIM(SUBSTITUTE(C38,"###"," "))) -> Groceries | O38: =PROPER(TRIM(SUBSTITUTE(D38,"###"," "))) -> Retailmart Inc | P38: =IF(M38="","Unknown",M38) -> Kitchen X | Q38: =IF(N38="","Unknown",N38) -> Groceries | R38: =IF(O38="","Others",O38) -> Retailmart Inc | S38: =VALUE(E38) -> 197 | T38: =VALUE(F38) -> 91 | U38: =VALUE(G38) -> 10705.08 | V38: =E38*G38 -> 2108900.8 | W38: In Stock | X38: No | Y38: 0
A39: P5413 | B39: Anyone X | C39: Furniture | D39: QuickStock | E39: 164 | F39: 70 | G39: 5424.78 | H39: 889663.92 | I39: 45800 | J39: 45916 | K39: Inactive | L39: Delhi Warehouse | M39: =PROPER(TRIM(SUBSTITUTE(B39,"###"," "))) -> Anyone X | N39: =PROPER(TRIM(SUBSTITUTE(C39,"###"," "))) -> Furniture | O39: =PROPER(TRIM(SUBSTITUTE(D39,"###"," "))) -> Quickstock | P39: =IF(M39="","Unknown",M39) -> Anyone X | Q39: =IF(N39="","Unknown",N39) -> Furniture | R39: =IF(O39="","Others",O39) -> Quickstock | S39: =VALUE(E39) -> 164 | T39: =VALUE(F39) -> 70 | U39: =VALUE(G39) -> 5424.78 | V39: =E39*G39 -> 889663.92 | W39: In Stock | X39: No | Y39: 0
A40: P1663 | B40: Peace Lite | C40: Furniture | D40: QuickStock | E40: 58 | F40: 51 | G40: 10399.87 | H40: 603192.46 | I40: 45787 | J40: 45895 | K40: Inactive | L40: Online | M40: =PROPER(TRIM(SUBSTITUTE(B40,"###"," "))) -> Peace Lite | N40: =PROPER(TRIM(SUBSTITUTE(C40,"###"," "))) -> Furniture | O40: =PROPER(TRIM(SUBSTITUTE(D40,"###"," "))) -> Quickstock | P40: =IF(M40="","Unknown",M40) -> Peace Lite | Q40: =IF(N40="","Unknown",N40) -> Furniture | R40: =IF(O40="","Others",O40) -> Quickstock | S40: =VALUE(E40) -> 58 | T40: =VALUE(F40) -> 51 | U40: =VALUE(G40) -> 10399.87 | V40: =E40*G40 -> 603192.46 | W40: In Stock | X40: No | Y40: 0
...

Sheet Pivot Summary
F2: Category | G2: Sum of Total Value (₹) | I2: Supplier Name | J2: Count of Product ID | L2: Last Restocked Month | M2: Sum of Restock Flag | O2: Category | P2: Sum of Quantity in Stock | R2: Stock Status | S2: Count of Product ID | U2: Recorder Tag | V2: Yes | X2: Recorder Tag | Y2: Yes | AA2: Sr.No. | AB2: KPIs | AE2: Sr.No. | AF2: Dropdown Dynamic
F3: Clothing | G3: 6.5487105e+08 | I3: Omni Suppliers | J3: 736 | L3: Jan | M3: 134 | O3: Clothing | P3: 67146 | R3: In Stock | S3: 2595 | AA3: 1 | AB3: Total Inventory Value | AC3: =SUM(Total_Value) -> 3.5971464e+09 | AE3: 1 | AF3: Product Name →
F4: Electronics | G4: 6.796797e+08 | I4: Global Traders | J4: 729 | L4: Feb | M4: 192 | O4: Electronics | P4: 67482 | R4: Low Stock | S4: 997 | U4: Product Name | V4: Sum of Quantity in Stock2 | X4: Product Name | Y4: Sum of Quantity in Stock | AA4: 2 | AB4: % Low Stock Items | AC4: =COUNTIF(Stock_Status,"Low Stock")/COUNTA(Product_ID) -> 0.26195481
F5: Toys | G5: 7.421721e+08 | I5: Abc Pvt Ltd | J5: 728 | L5: Mar | M5: 194 | O5: Furniture | P5: 74914 | R5: Out of Stock | S5: 214 | U5: A Mini | V5: 0 | X5: A Mini | Y5: 0 | AA5: 3 | AB5: Upcoming Restocks | AC5: =COUNTIF(Stock_Status,"Low Stock") -> 997
F6: Groceries | G6: 7.5042811e+08 | I6: Quickstock | J6: 718 | L6: Apr | M6: 196 | O6: Groceries | P6: 73833 | R6: Grand Total | S6: 3806 | U6: A Plus | V6: 35 | X6: Electronics | Y6: 0 | AA6: 4 | AB6: Total Products | AC6: =COUNTA(Product_ID) -> 3806
F7: Furniture | G7: 7.699954e+08 | I7: Retailmart Inc | J7: 710 | L7: May | M7: 193 | O7: Toys | P7: 75593 | U7: About Lite | V7: 31 | X7: Omni Suppliers | Y7: 0 | AA7: 5 | AB7: Low Stock (Items) Count | AC7: =COUNTIF(Recorder_Tag,"Yes") -> 1190
F8: Grand Total | G8: 3.5971464e+09 | I8: Others | J8: 185 | L8: Jun | M8: 215 | O8: Grand Total | P8: 358968 | U8: About Max | V8: 1 | X8: A Plus | Y8: 35 | AA8: 6 | AB8: Out of Stock Items | AC8: =COUNTIF(Stock_Status,"Out of Stock") -> 214
F9: ● This will give category-wise inventory value | I9: Grand Total | J9: 3806 | L9: Jul | M9: 87 | U9: Accept Lite | V9: 0 | X9: Groceries | Y9: 35
I10: ● Shows supplier contribution | L10: Grand Total | M10: 1211 | U10: Accept Max | V10: 59 | X10: Abc Pvt Ltd | Y10: 35
L11: ● This shows how many items needed restock over time | U11: Accept Mini | V11: 44 | X11: About Lite | Y11: 31
U12: Account X | V12: 6 | X12: Groceries | Y12: 31
U13: Act Lite | V13: 54 | X13: Abc Pvt Ltd | Y13: 31
U14: Action Max | V14: 6 | X14: About Max | Y14: 1
U15: Address Plus | V15: 36 | X15: Toys | Y15: 1
L16: 2 | U16: Administration X | V16: 31 | X16: Quickstock | Y16: 1
U17: Adult Plus | V17: 0 | X17: Accept Lite | Y17: 0
U18: Affect Lite | V18: 53 | X18: Toys | Y18: 0
U19: Affect Mini | V19: 0 | X19: Quickstock | Y19: 0
U20: After Lite | V20: 68 | X20: Accept Max | Y20: 59
U21: After Mini | V21: 0 | X21: Groceries | Y21: 59
U22: Again Mini | V22: 54 | X22: Abc Pvt Ltd | Y22: 59
U23: Again Plus | V23: 16 | X23: Accept Mini | Y23: 44
U24: Against Lite | V24: 13 | X24: Clothing | Y24: 44
U25: Against Mini | V25: 0 | X25: Abc Pvt Ltd | Y25: 44
U26: Against X | V26: 49 | X26: Account X | Y26: 6
U27: Age Plus | V27: 28 | X27: Groceries | Y27: 6
U28: Age X | V28: 24 | X28: Retailmart Inc | Y28: 6
... U1091: Grand Total | V1091: 33098 | X1091: Quickstock | Y1091: 24
X1092: Firm Pro | Y1092: 0
X1093: Furniture | Y1093: 0
X1094: Abc Pvt Ltd | Y1094: 0
X1095: First Lite | Y1095: 31
X1096: Furniture | Y1096: 31
X1097: Abc Pvt Ltd | Y1097: 31
X1098: First Plus | Y1098: 81
X1099: Furniture | Y1099: 81
X1100: Abc Pvt Ltd | Y1100: 81
X1101: Fish Lite | Y1101: 57
X1102: Furniture | Y1102: 57
X1103: Abc Pvt Ltd | Y1103: 57
...

Sheet Dashboard
G49: Top Category
G50: Top Store

Sheet Insights Summary
G1: 1 | H1: 2 Product Name | I1: Low Stock | K1: 2 | L1: =SUM(Total_Value) -> 3.5971464e+09 | N1: 3 | O1: Highest contributing category | R1: 4 | S1: Highest-value inventory provider | V1: 5 | W1: Store Location Has Largest Stock Value | Z1: 6 | AA1: Products Overdue for Restock (01-09-2025) | AB1: Next Restock Due | AC1: 45901 | AE1: 7 | AF1: Average Unit Cost Across Categories | AI1: 8 | AJ1: Products with Highest Holding Cost | AM1: 9 | AN1: Risk if Sales Increase by 10% | AO1: New Stock | AP1: Risk | AR1: 10 | AS1: Inventory Optimization Strategy:
G2: ● Products are low in stock. These are your urgent reorder products. → | H2: Management Plus | I2: {=IF(Quantity_in_Stock<=Recorder_Level,"Low Stock","In Stock")} -> In Stock | K2: ● Total Stock Value Across All Stores/KPI: Total Inventory Value | O2: Category | P2: Sum of Total Value (₹) | S2: Supplier Name | T2: Sum of Total Value (₹) | W2: Store Location | X2: Sum of Total Value (₹)2 | AA2: =COUNTIF(Overdues,"Overdue") -> 2087 | AB2: 45883 | AC2: =IF(AB2="","No Date", IF(AB2<$AC$1,"Overdue","OnTime")) -> Overdue | AF2: Store Location | AG2: Average of Cost per unit(₹) | AJ2: Store Location | AK2: Sum of Total Value (₹) | AN2: ●Filter = "Risk". These products may run out first | AO2: =(Cleaned_Data!S2)-((Cleaned_Data!S2)*10%) -> 161.1 | AP2: {=IF(Quantity_in_Stock*0.9<Recorder_Level,"Risk","Safe")} -> Safe
H3: Glass Mini | I3: In Stock | O3: Furniture | P3: 7.699954e+08 | S3: Omni Suppliers | T3: 7.1489253e+08 | W3: Ahmedabad Branch | X3: 6.7369462e+08 | AA3: KPIs ↑ | AB3: 45886 | AC3: =IF(AB3="","No Date", IF(AB3<$AC$1,"Overdue","OnTime")) -> Overdue | AF3: Clothing | AG3: 9703.2206 | AJ3: Behind Max | AK3: 8220460.9 | AO3: =(Cleaned_Data!S3)-((Cleaned_Data!S3)*10%) -> 108.9 | AP3: Safe
H4: Government Max | I4: Low Stock | O4: Groceries | P4: 7.5042811e+08 | S4: Abc Pvt Ltd | T4: 7.0479029e+08 | W4: Delhi Warehouse | X4: 6.9309559e+08 | AA4: ●Filter = "Overdue". | AB4: 45906 | AC4: =IF(AB4="","No Date", IF(AB4<$AC$1,"Overdue","OnTime")) -> OnTime | AF4: Electronics | AG4: 10026.24 | AJ4: Nature Pro | AK4: 7479908.7 | AO4: =(Cleaned_Data!S4)-((Cleaned_Data!S4)*10%) -> 0 | AP4: Risk
H5: Kitchen Plus | I5: In Stock | O5: Toys | P5: 7.421721e+08 | S5: Global Traders | T5: 6.8393791e+08 | W5: Mumbai Store | X5: 7.1340887e+08 | AB5: 45898 | AC5: =IF(AB5="","No Date", IF(AB5<$AC$1,"Overdue","OnTime")) -> Overdue | AF5: Furniture | AG5: 10171.314 | AJ5: Start Pro | AK5: 7266179.3 | AO5: =(Cleaned_Data!S5)-((Cleaned_Data!S5)*10%) -> 116.1 | AP5: Safe
G6: ●Filter = "Low Stock". | H6: Image X | I6: In Stock | O6: Electronics | P6: 6.796797e+08 | S6: Retailmart Inc | T6: 6.712211e+08 | W6: Online | X6: 7.8588434e+08 | AB6: 45896 | AC6: =IF(AB6="","No Date", IF(AB6<$AC$1,"Overdue","OnTime")) -> Overdue | AF6: Groceries | AG6: 9943.6151 | AJ6: Success Lite | AK6: 6846568.9 | AO6: =(Cleaned_Data!S6)-((Cleaned_Data!S6)*10%) -> 51.3 | AP6: Safe
H7: Computer Plus | I7: Low Stock | O7: Clothing | P7: 6.5487105e+08 | S7: Quickstock | T7: 6.5564155e+08 | W7: Pune Store | X7: 731062935 | AB7: 45926 | AC7: =IF(AB7="","No Date", IF(AB7<$AC$1,"Overdue","OnTime")) -> OnTime | AF7: Toys | AG7: 9764.5471 | AJ7: Name Plus | AK7: 6726797.6 | AO7: =(Cleaned_Data!S7)-((Cleaned_Data!S7)*10%) -> 52.2 | AP7: Risk
H8: Democrat Lite | I8: Low Stock | O8: Grand Total | P8: 3.5971464e+09 | S8: Grand Total | T8: 3.4304834e+09 | W8: Grand Total | X8: 3.5971464e+09 | AB8: 45875 | AC8: =IF(AB8="","No Date", IF(AB8<$AC$1,"Overdue","OnTime")) -> Overdue | AF8: Grand Total | AG8: 9924.1435 | AJ8: Her Mini | AK8: 6648296.9 | AO8: =(Cleaned_Data!S8)-((Cleaned_Data!S8)*10%) -> 12.6 | AP8: Risk
H9: Hundred Lite | I9: Low Stock | AB9: 45868 | AC9: =IF(AB9="","No Date", IF(AB9<$AC$1,"Overdue","OnTime")) -> Overdue | AJ9: Indicate Pro | AK9: 6563411.6 | AO9: =(Cleaned_Data!S9)-((Cleaned_Data!S9)*10%) -> 45 | AP9: Risk
H10: Plan Plus | I10: In Stock | AB10: 45888 | AC10: =IF(AB10="","No Date", IF(AB10<$AC$1,"Overdue","OnTime")) -> Overdue | AJ10: His Max | AK10: 6416079.2 | AO10: =(Cleaned_Data!S10)-((Cleaned_Data!S10)*10%) -> 117 | AP10: Safe
H11: Change Pro | I11: In Stock | AB11: 45853 | AC11: =IF(AB11="","No Date", IF(AB11<$AC$1,"Overdue","OnTime")) -> Overdue | AJ11: Eat Plus | AK11: 6269198.1 | AO11: =(Cleaned_Data!S11)-((Cleaned_Data!S11)*10%) -> 117.9 | AP11: Safe
H12: Deep Max | I12: In Stock | AB12: 45918 | AC12: =IF(AB12="","No Date", IF(AB12<$AC$1,"Overdue","OnTime")) -> OnTime | AJ12: Relationship Lite | AK12: 6156348.6 | AO12: =(Cleaned_Data!S12)-((Cleaned_Data!S12)*10%) -> 46.8 | AP12: Safe
H13: Find X | I13: In Stock | AB13: 45940 | AC13: =IF(AB13="","No Date", IF(AB13<$AC$1,"Overdue","OnTime")) -> OnTime | AJ13: Woman X | AK13: 6147064.1 | AO13: =(Cleaned_Data!S13)-((Cleaned_Data!S13)*10%) -> 168.3 | AP13: Safe
H14: Nothing Lite | I14: In Stock | AB14: 45868 | AC14: =IF(AB14="","No Date", IF(AB14<$AC$1,"Overdue","OnTime")) -> Overdue | AJ14: Anyone X | AK14: 6134253.8 | AO14: =(Cleaned_Data!S14)-((Cleaned_Data!S14)*10%) -> 156.6 | AP14: Safe
H15: Wait Max | I15: In Stock | AB15: 45899 | AC15: =IF(AB15="","No Date", IF(AB15<$AC$1,"Overdue","OnTime")) -> Overdue | AJ15: Outside Plus | AK15: 6079891.9 | AO15: =(Cleaned_Data!S15)-((Cleaned_Data!S15)*10%) -> 92.7 | AP15: Safe
H16: Old Mini | I16: Low Stock | AB16: 45914 | AC16: =IF(AB16="","No Date", IF(AB16<$AC$1,"Overdue","OnTime")) -> OnTime | AJ16: Recently Lite | AK16: 6059897.3 | AO16: =(Cleaned_Data!S16)-((Cleaned_Data!S16)*10%) -> 47.7 | AP16: Risk
H17: Before Lite | I17: In Stock | AB17: 45873 | AC17: =IF(AB17="","No Date", IF(AB17<$AC$1,"Overdue","OnTime")) -> Overdue | AJ17: Already Max | AK17: 6044166.8 | AO17: =(Cleaned_Data!S17)-((Cleaned_Data!S17)*10%) -> 144.9 | AP17: Safe
H18: Support Plus | I18: In Stock | AB18: 45864 | AC18: =IF(AB18="","No Date", IF(AB18<$AC$1,"Overdue","OnTime")) -> Overdue | AJ18: Real Lite | AK18: 6026385.4 | AO18: =(Cleaned_Data!S18)-((Cleaned_Data!S18)*10%) -> 170.1 | AP18: Safe
H19: Else Pro | I19: In Stock | AB19: 45890 | AC19: =IF(AB19="","No Date", IF(AB19<$AC$1,"Overdue","OnTime")) -> Overdue | AJ19: Common X | AK19: 5846596.2 | AO19: =(Cleaned_Data!S19)-((Cleaned_Data!S19)*10%) -> 72.9 | AP19: Safe
H20: When Lite | I20: In Stock | AB20: 45940 | AC20: =IF(AB20="","No Date", IF(AB20<$AC$1,"Overdue","OnTime")) -> OnTime | AJ20: Quite Mini | AK20: 5800269.6 | AO20: =(Cleaned_Data!S20)-((Cleaned_Data!S20)*10%) -> 168.3 | AP20: Safe
... H2774: Firm Lite | I2774: In Stock | AB2774: 45918 | AC2774: =IF(AB2774="","No Date", IF(AB2774<$AC$1,"Overdue","OnTime")) -> OnTime | AJ2774: Grand Total | AK2774: 3.5971464e+09 | AO2774: =(Cleaned_Data!S2774)-((Cleaned_Data!S2774)*10%) -> 140.4 | AP2774: Safe
H2775: Who Plus | I2775: Low Stock | AB2775: 45921 | AC2775: =IF(AB2775="","No Date", IF(AB2775<$AC$1,"Overdue","OnTime")) -> OnTime | AO2775: =(Cleaned_Data!S2775)-((Cleaned_Data!S2775)*10%) -> 10.8 | AP2775: Risk
H2776: Half Pro | I2776: In Stock | AB2776: 45869 | AC2776: =IF(AB2776="","No Date", IF(AB2776<$AC$1,"Overdue","OnTime")) -> Overdue | AO2776: =(Cleaned_Data!S2776)-((Cleaned_Data!S2776)*10%) -> 128.7 | AP2776: Safe
H2777: His Max | I2777: In Stock | AB2777: 45855 | AC2777: =IF(AB2777="","No Date", IF(AB2777<$AC$1,"Overdue","OnTime")) -> Overdue | AO2777: =(Cleaned_Data!S2777)-((Cleaned_Data!S2777)*10%) -> 166.5 | AP2777: Safe
H2778: See Max | I2778: In Stock | AB2778: 45881 | AC2778: =IF(AB2778="","No Date", IF(AB2778<$AC$1,"Overdue","OnTime")) -> Overdue | AO2778: =(Cleaned_Data!S2778)-((Cleaned_Data!S2778)*10%) -> 170.1 | AP2778: Safe
H2779: Bit Mini | I2779: In Stock | AB2779: 45871 | AC2779: =IF(AB2779="","No Date", IF(AB2779<$AC$1,"Overdue","OnTime")) -> Overdue | AO2779: =(Cleaned_Data!S2779)-((Cleaned_Data!S2779)*10%) -> 133.2 | AP2779: Safe
H2780: Teach Pro | I2780: Low Stock | AB2780: 45853 | AC2780: =IF(AB2780="","No Date", IF(AB2780<$AC$1,"Overdue","OnTime")) -> Overdue | AO2780: =(Cleaned_Data!S2780)-((Cleaned_Data!S2780)*10%) -> 26.1 | AP2780: Risk
H2781: Trip Plus | I2781: In Stock | AB2781: 45888 | AC2781: =IF(AB2781="","No Date", IF(AB2781<$AC$1,"Overdue","OnTime")) -> Overdue | AO2781: =(Cleaned_Data!S2781)-((Cleaned_Data!S2781)*10%) -> 120.6 | AP2781: Safe
H2782: Wait Mini | I2782: In Stock | AB2782: 45875 | AC2782: =IF(AB2782="","No Date", IF(AB2782<$AC$1,"Overdue","OnTime")) -> Overdue | AO2782: =(Cleaned_Data!S2782)-((Cleaned_Data!S2782)*10%) -> 124.2 | AP2782: Safe
H2783: Usually Plus | I2783: In Stock | AB2783: 45902 | AC2783: =IF(AB2783="","No Date", IF(AB2783<$AC$1,"Overdue","OnTime")) -> OnTime | AO2783: =(Cleaned_Data!S2783)-((Cleaned_Data!S2783)*10%) -> 146.7 | AP2783: Safe
H2784: Military Pro | I2784: In Stock | AB2784: 45924 | AC2784: =IF(AB2784="","No Date", IF(AB2784<$AC$1,"Overdue","OnTime")) -> OnTime | AO2784: =(Cleaned_Data!S2784)-((Cleaned_Data!S2784)*10%) -> 174.6 | AP2784: Safe
H2785: Rich Mini | I2785: In Stock | AB2785: 45871 | AC2785: =IF(AB2785="","No Date", IF(AB2785<$AC$1,"Overdue","OnTime")) -> Overdue | AO2785: =(Cleaned_Data!S2785)-((Cleaned_Data!S2785)*10%) -> 126.9 | AP2785: Safe
H2786: Event Plus | I2786: In Stock | AB2786: 45912 | AC2786: =IF(AB2786="","No Date", IF(AB2786<$AC$1,"Overdue","OnTime")) -> OnTime | AO2786: =(Cleaned_Data!S2786)-((Cleaned_Data!S2786)*10%) -> 166.5 | AP2786: Safe
... H3807: Civil Pro | I3807: In Stock | AB3807: 45913 | AC3807: =IF(AB3807="","No Date", IF(AB3807<$AC$1,"Overdue","OnTime")) -> OnTime | AO3807: =(Cleaned_Data!S3807)-((Cleaned_Data!S3807)*10%) -> 81 | AP3807: Safe
AO3808: =(Cleaned_Data!S3808)-((Cleaned_Data!S3808)*10%) -> 0
AO3809: =(Cleaned_Data!S3809)-((Cleaned_Data!S3809)*10%) -> 0
AO3810: =(Cleaned_Data!S3810)-((Cleaned_Data!S3810)*10%) -> 0
AO3811: =(Cleaned_Data!S3811)-((Cleaned_Data!S3811)*10%) -> 0
AO3812: =(Cleaned_Data!S3812)-((Cleaned_Data!S3812)*10%) -> 0
AO3813: =(Cleaned_Data!S3813)-((Cleaned_Data!S3813)*10%) -> 0
...

Sheet Restock Order Form
A1: Product | B1: Quantity in Stock | C1: Reorder Level | D1: Order Quantity | E1: Order Quantity 1 | F1: Order Quantity 2 | G1: Order Quantity Status | H1: Buffer Stock | I1: Status
A2: Management Plus | B2: =VLOOKUP(A2,VLookup_Data,4,FALSE) -> 179 | C2: =_xlfn.XLOOKUP(A2,Product_Name,Recorder_Level) -> 34 | D2: =IF(B2<=C2,C2-B2,0) -> 0 | E2: =IF(C2-B2>0,C2-B2,0) -> 0 | F2: =MAX(C2-B2,0) -> 0 | G2: =IF(B2<=C2,C2-B2,"No Order Needed") -> No Order Needed | H2: =MAX((C2-B2)+10,0) -> 0 | I2: =IF(B2=0,"Urgent",IF(B2<=C2,"Reorder","Ok")) -> Ok
A3: Glass Mini | B3: =VLOOKUP(A3,VLookup_Data,4,FALSE) -> 121 | C3: =_xlfn.XLOOKUP(A3,Product_Name,Recorder_Level) -> 94 | D3: =IF(B3<=C3,C3-B3,0) -> 0 | E3: =IF(C3-B3>0,C3-B3,0) -> 0 | F3: =MAX(C3-B3,0) -> 0 | G3: =IF(B3<=C3,C3-B3,"No Order Needed") -> No Order Needed | H3: =MAX((C3-B3)+10,0) -> 0 | I3: =IF(B3=0,"Urgent",IF(B3<=C3,"Reorder","Ok")) -> Ok
A4: Government Max | B4: =VLOOKUP(A4,VLookup_Data,4,FALSE) -> 0 | C4: =_xlfn.XLOOKUP(A4,Product_Name,Recorder_Level) -> 72 | D4: =IF(B4<=C4,C4-B4,0) -> 72 | E4: =IF(C4-B4>0,C4-B4,0) -> 72 | F4: =MAX(C4-B4,0) -> 72 | G4: =IF(B4<=C4,C4-B4,"No Order Needed") -> 72 | H4: =MAX((C4-B4)+10,0) -> 82 | I4: =IF(B4=0,"Urgent",IF(B4<=C4,"Reorder","Ok")) -> Urgent
A5: Kitchen Plus | B5: =VLOOKUP(A5,VLookup_Data,4,FALSE) -> 129 | C5: =_xlfn.XLOOKUP(A5,Product_Name,Recorder_Level) -> 83 | D5: =IF(B5<=C5,C5-B5,0) -> 0 | E5: =IF(C5-B5>0,C5-B5,0) -> 0 | F5: =MAX(C5-B5,0) -> 0 | G5: =IF(B5<=C5,C5-B5,"No Order Needed") -> No Order Needed | H5: =MAX((C5-B5)+10,0) -> 0 | I5: =IF(B5=0,"Urgent",IF(B5<=C5,"Reorder","Ok")) -> Ok
A6: Image X | B6: =VLOOKUP(A6,VLookup_Data,4,FALSE) -> 57 | C6: =_xlfn.XLOOKUP(A6,Product_Name,Recorder_Level) -> 41 | D6: =IF(B6<=C6,C6-B6,0) -> 0 | E6: =IF(C6-B6>0,C6-B6,0) -> 0 | F6: =MAX(C6-B6,0) -> 0 | G6: =IF(B6<=C6,C6-B6,"No Order Needed") -> No Order Needed | H6: =MAX((C6-B6)+10,0) -> 0 | I6: =IF(B6=0,"Urgent",IF(B6<=C6,"Reorder","Ok")) -> Ok
A7: Computer Plus | B7: =VLOOKUP(A7,VLookup_Data,4,FALSE) -> 58 | C7: =_xlfn.XLOOKUP(A7,Product_Name,Recorder_Level) -> 61 | D7: =IF(B7<=C7,C7-B7,0) -> 3 | E7: =IF(C7-B7>0,C7-B7,0) -> 3 | F7: =MAX(C7-B7,0) -> 3 | G7: =IF(B7<=C7,C7-B7,"No Order Needed") -> 3 | H7: =MAX((C7-B7)+10,0) -> 13 | I7: =IF(B7=0,"Urgent",IF(B7<=C7,"Reorder","Ok")) -> Reorder
A8: Democrat Lite | B8: =VLOOKUP(A8,VLookup_Data,4,FALSE) -> 14 | C8: =_xlfn.XLOOKUP(A8,Product_Name,Recorder_Level) -> 81 | D8: =IF(B8<=C8,C8-B8,0) -> 67 | E8: =IF(C8-B8>0,C8-B8,0) -> 67 | F8: =MAX(C8-B8,0) -> 67 | G8: =IF(B8<=C8,C8-B8,"No Order Needed") -> 67 | H8: =MAX((C8-B8)+10,0) -> 77 | I8: =IF(B8=0,"Urgent",IF(B8<=C8,"Reorder","Ok")) -> Reorder
A9: Hundred Lite | B9: =VLOOKUP(A9,VLookup_Data,4,FALSE) -> 50 | C9: =_xlfn.XLOOKUP(A9,Product_Name,Recorder_Level) -> 74 | D9: =IF(B9<=C9,C9-B9,0) -> 24 | E9: =IF(C9-B9>0,C9-B9,0) -> 24 | F9: =MAX(C9-B9,0) -> 24 | G9: =IF(B9<=C9,C9-B9,"No Order Needed") -> 24 | H9: =MAX((C9-B9)+10,0) -> 34 | I9: =IF(B9=0,"Urgent",IF(B9<=C9,"Reorder","Ok")) -> Reorder
A10: Plan Plus | B10: =VLOOKUP(A10,VLookup_Data,4,FALSE) -> 130 | C10: =_xlfn.XLOOKUP(A10,Product_Name,Recorder_Level) -> 70 | D10: =IF(B10<=C10,C10-B10,0) -> 0 | E10: =IF(C10-B10>0,C10-B10,0) -> 0 | F10: =MAX(C10-B10,0) -> 0 | G10: =IF(B10<=C10,C10-B10,"No Order Needed") -> No Order Needed | H10: =MAX((C10-B10)+10,0) -> 0 | I10: =IF(B10=0,"Urgent",IF(B10<=C10,"Reorder","Ok")) -> Ok
A11: Change Pro | B11: =VLOOKUP(A11,VLookup_Data,4,FALSE) -> 131 | C11: =_xlfn.XLOOKUP(A11,Product_Name,Recorder_Level) -> 79 | D11: =IF(B11<=C11,C11-B11,0) -> 0 | E11: =IF(C11-B11>0,C11-B11,0) -> 0 | F11: =MAX(C11-B11,0) -> 0 | G11: =IF(B11<=C11,C11-B11,"No Order Needed") -> No Order Needed | H11: =MAX((C11-B11)+10,0) -> 0 | I11: =IF(B11=0,"Urgent",IF(B11<=C11,"Reorder","Ok")) -> Ok
A12: Deep Max | B12: =VLOOKUP(A12,VLookup_Data,4,FALSE) -> 52 | C12: =_xlfn.XLOOKUP(A12,Product_Name,Recorder_Level) -> 21 | D12: =IF(B12<=C12,C12-B12,0) -> 0 | E12: =IF(C12-B12>0,C12-B12,0) -> 0 | F12: =MAX(C12-B12,0) -> 0 | G12: =IF(B12<=C12,C12-B12,"No Order Needed") -> No Order Needed | H12: =MAX((C12-B12)+10,0) -> 0 | I12: =IF(B12=0,"Urgent",IF(B12<=C12,"Reorder","Ok")) -> Ok
A13: Find X | B13: =VLOOKUP(A13,VLookup_Data,4,FALSE) -> 187 | C13: =_xlfn.XLOOKUP(A13,Product_Name,Recorder_Level) -> 90 | D13: =IF(B13<=C13,C13-B13,0) -> 0 | E13: =IF(C13-B13>0,C13-B13,0) -> 0 | F13: =MAX(C13-B13,0) -> 0 | G13: =IF(B13<=C13,C13-B13,"No Order Needed") -> No Order Needed | H13: =MAX((C13-B13)+10,0) -> 0 | I13: =IF(B13=0,"Urgent",IF(B13<=C13,"Reorder","Ok")) -> Ok
... A3807: Civil Pro | B3807: =VLOOKUP(A3807,VLookup_Data,4,FALSE) -> 90 | C3807: =_xlfn.XLOOKUP(A3807,Product_Name,Recorder_Level) -> 41 | D3807: =IF(B3807<=C3807,C3807-B3807,0) -> 0 | E3807: =IF(C3807-B3807>0,C3807-B3807,0) -> 0 | F3807: =MAX(C3807-B3807,0) -> 0 | G3807: =IF(B3807<=C3807,C3807-B3807,"No Order Needed") -> No Order Needed | H3807: =MAX((C3807-B3807)+10,0) -> 0 | I3807: =IF(B3807=0,"Urgent",IF(B3807<=C3807,"Reorder","Ok")) -> Ok
